<?xml version="1.0" ?>

<robot name="quad">
    <link name="base_link">
    <visual>
    <origin rpy="0 0 0" xyz="0 0 0.32"/>
      <geometry>
        <box size="0.3 0.1 0.12"/>
      </geometry>
    </visual>
    <collision>
    <origin rpy="0 0 0" xyz="0 0 0.32"/>
      <geometry>
       <box size="0.3 0.1 0.12"/>
      </geometry>
    </collision>
    <inertial>
      <mass value="2"/>
      <inertia ixx="0.01366667" ixy="0.0" ixz="0.0" iyy="0.01293333" iyz="0.0" izz="4.06666667e-3"/>
        <origin  xyz="0 0 0.32"/>
    </inertial>
  </link>

<link name="base_sensor_weight">
    <visual>
    <origin rpy="0 0 0" xyz="0 0 0"/>
      <geometry>
        <sphere radius="0.01"/>
      </geometry>
    </visual>
     <collision>
    <origin rpy="0 0 0" xyz="0 0 0"/>
      <geometry>
        <sphere radius="0.01"/>
      </geometry>
    </collision>
    <inertial>
      <mass value="0.1"/>
      <inertia ixx="4e-6" ixy="0.0" ixz="0.0" iyy="4e-6" iyz="0.0" izz="4e-6"/>
    </inertial>
  </link>
  <joint name="base_sensor" type="fixed">
    <parent link="base_link"/>
    <child link="base_sensor_weight"/>
    <origin rpy="0 0 0" xyz="0 0 0.32"/>
    <joint_properties damping="0.0" friction="0.05"/>
  </joint>

<link name="back_right_shoulder_blade">
    <visual>
    <origin rpy="0 0 0" xyz="-0.035 0.01 -0.015"/>
      <geometry>
        <box size="0.07 0.02 0.03"/>
      </geometry>
    </visual>
    <collision>
    <origin rpy="0 0 0" xyz="-0.035 0.01 -0.015"/>
      <geometry>
        <box size="0.07 0.02 0.03"/>
      </geometry>
    </collision>
    <inertial>
      <mass value="0.07"/>
      <inertia ixx="3.38333333e-5" ixy="0.0" ixz="0.0" iyy="3.09166667e-5" iyz="0.0" izz="7.58333333e-6"/>
    </inertial>
  </link>
  <joint name="back_right_base_to_shoulder" type="revolute">
    <axis xyz="1 0 0"/>
    <parent link="base_link"/>
    <child link="back_right_shoulder_blade"/>
    <origin rpy="0 0 0" xyz="0.15 0.05 0.26"/>
    <limit effort="200" velocity="7.4799" lower="-0.24497866" upper="0.5235988" />
    <joint_properties damping="0.5" friction="0.05"/>
  </joint>

  <link name="back_right_upper">
    <visual>
    <origin rpy="0 0 0" xyz="0 0 -0.05"/>
      <geometry>
        <box size="0.03 0.02 0.1"/>
      </geometry>
    </visual>
    <collision>
    <origin rpy="0 0 0" xyz="0 0 -0.05"/>
      <geometry>
        <box size="0.03 0.02 0.1"/>
      </geometry>
    </collision>
    <inertial>
      <mass value="0.2"/>
      <inertia ixx="2.48333333e-4" ixy="0.0" ixz="0.0" iyy="8.83333333e-5" iyz="0.0" izz="1.73333333e-4"/>
    </inertial>
  </link>
  <joint name="back_right_shoulder" type="revolute">
    <axis xyz="0 1 0"/>
    <parent link="back_right_shoulder_blade"/>
    <child link="back_right_upper"/>
    <origin rpy="0 0 0" xyz="-0.025 0.01 -0.03"/>
    <limit effort="530" velocity="8.7266" lower="-0.5235988" upper="1.48353" />
    <joint_properties damping="0.0" friction="0.05"/>
  </joint>

<link name="back_right_lower">
    <visual>
    <origin rpy="0 0 0" xyz="0 0 -0.05"/>
      <geometry>
        <cylinder length="0.095" radius="0.005"/>
      </geometry>
    </visual>
    <collision>
    <origin rpy="0 0 0" xyz="0 0 -0.05"/>
      <geometry>
        <cylinder length="0.095" radius="0.005"/>
      </geometry>
    </collision>
    <inertial>
      <mass value="0.15"/>
      <inertia ixx="1.25e-4" ixy="0.0" ixz="0.0" iyy="0.0" iyz="0.0" izz="1.25e-4"/>
    </inertial>
  </link>
  <joint name="back_right_knee" type="revolute">
    <axis xyz="0 1 0"/>
    <parent link="back_right_upper"/>
    <child link="back_right_lower"/>
    <origin rpy="0 0 0" xyz="0 0 -0.1"/>
    <limit effort="330" velocity="7.4799" lower="-0.5235988" upper="-2.094395" />
    <joint_properties damping="0.0" friction="0.05"/>
  </joint>

  <link name="back_right_foot">
    <visual>
    <origin rpy="0 0 0" xyz="0 0 0"/>
      <geometry>
        <sphere radius="0.006"/>
      </geometry>
    </visual>
     <collision>
    <origin rpy="0 0 0" xyz="0 0 0"/>
      <geometry>
        <sphere radius="0.006"/>
      </geometry>
    </collision>
    <inertial>
      <mass value="0"/>
      <inertia ixx="0" ixy="0.0" ixz="0.0" iyy="0.0" iyz="0.0" izz="0"/>
    </inertial>
  </link>
  <joint name="back_right_sensor" type="fixed">
    <parent link="back_right_lower"/>
    <child link="back_right_foot"/>
    <origin rpy="0 0 0" xyz="0 0 -0.0975"/>
    <joint_properties damping="0.0" friction="0.05"/>
  </joint>

<link name="front_right_shoulder_blade">
    <visual>
    <origin rpy="0 0 0" xyz="0.035 0.01 -0.015"/>
      <geometry>
        <box size="0.07 0.02 0.03"/>
      </geometry>
    </visual>
    <collision>
    <origin rpy="0 0 0" xyz="0.035 0.01 -0.015"/>
      <geometry>
        <box size="0.07 0.02 0.03"/>
      </geometry>
    </collision>
    <inertial>
      <mass value="0.07"/>
      <inertia ixx="3.38333333e-5" ixy="0.0" ixz="0.0" iyy="3.09166667e-5" iyz="0.0" izz="7.58333333e-6"/>
    </inertial>
  </link>
  <joint name="front_right_base_to_shoulder" type="revolute">
    <axis xyz="1 0 0"/>
    <parent link="base_link"/>
    <child link="front_right_shoulder_blade"/>
    <origin rpy="0 0 0" xyz="-0.15 0.05 0.26"/>
    <limit effort="200" velocity="7.4799" lower="-0.24497866" upper="0.5235988" />
    <joint_properties damping="0.0" friction="0.05"/>
  </joint>

  <link name="front_right_upper">
    <visual>
    <origin rpy="0 0 0" xyz="0 0 -0.05"/>
      <geometry>
        <box size="0.03 0.02 0.1"/>
      </geometry>
    </visual>
    <collision>
    <origin rpy="0 0 0" xyz="0 0 -0.05"/>
      <geometry>
        <box size="0.03 0.02 0.1"/>
      </geometry>
    </collision>
    <inertial>
      <mass value="0.2"/>
      <inertia ixx="2.48333333e-4" ixy="0.0" ixz="0.0" iyy="8.83333333e-5" iyz="0.0" izz="1.73333333e-4"/>
    </inertial>
  </link>
  <joint name="front_right_shoulder" type="revolute">
    <axis xyz="0 1 0"/>
    <parent link="front_right_shoulder_blade"/>
    <child link="front_right_upper"/>
    <origin rpy="0 0 0" xyz="0.025 0.01 -0.03"/>
    <limit effort="530" velocity="8.7266" lower="-1.48353" upper="0.5235988" />
    <joint_properties damping="0.0" friction="0.05"/>
  </joint>

<link name="front_right_lower">
    <visual>
    <origin rpy="0 0 0" xyz="0 0 -0.05"/>
      <geometry>
        <cylinder length="0.095" radius="0.005"/>
      </geometry>
    </visual>
    <collision>
    <origin rpy="0 0 0" xyz="0 0 -0.05"/>
      <geometry>
        <cylinder length="0.095" radius="0.005"/>
      </geometry>
    </collision>
    <inertial>
      <mass value="0.15"/>
      <inertia ixx="1.25e-4" ixy="0.0" ixz="0.0" iyy="0.0" iyz="0.0" izz="1.25e-4"/>
    </inertial>
  </link>
  <joint name="front_right_knee" type="revolute">
    <axis xyz="0 1 0"/>
    <parent link="front_right_upper"/>
    <child link="front_right_lower"/>
    <origin rpy="0 0 0" xyz="0 0 -0.1"/>
    <limit effort="330" velocity="7.4799" lower="0.5235988" upper="2.094395" />
    <joint_properties damping="0.0" friction="0.05"/>
  </joint>

  <link name="front_right_foot">
    <visual>
    <origin rpy="0 0 0" xyz="0 0 0"/>
      <geometry>
        <sphere radius="0.006"/>
      </geometry>
    </visual>
     <collision>
    <origin rpy="0 0 0" xyz="0 0 0"/>
      <geometry>
        <sphere radius="0.006"/>
      </geometry>
    </collision>
    <inertial>
      <mass value="0"/>
      <inertia ixx="0" ixy="0.0" ixz="0.0" iyy="0.0" iyz="0.0" izz="0"/>
    </inertial>
  </link>
  <joint name="front_right_sensor" type="fixed">
    <parent link="front_right_lower"/>
    <child link="front_right_foot"/>
    <origin rpy="0 0 0" xyz="0 0 -0.0975"/>
    <joint_properties damping="0.0" friction="0.05"/>
  </joint>

<link name="back_left_shoulder_blade">
    <visual>
    <origin rpy="0 0 0" xyz="-0.035 -0.01 -0.015"/>
      <geometry>
        <box size="0.07 0.02 0.03"/>
      </geometry>
    </visual>
    <collision>
    <origin rpy="0 0 0" xyz="-0.035 -0.01 -0.015"/>
      <geometry>
        <box size="0.07 0.02 0.03"/>
      </geometry>
    </collision>
    <inertial>
      <mass value="0.07"/>
      <inertia ixx="3.38333333e-5" ixy="0.0" ixz="0.0" iyy="3.09166667e-5" iyz="0.0" izz="7.58333333e-6"/>
    </inertial>
  </link>
  <joint name="back_left_base_to_shoulder" type="revolute">
    <axis xyz="1 0 0"/>
    <parent link="base_link"/>
    <child link="back_left_shoulder_blade"/>
    <origin rpy="0 0 0" xyz="0.15 -0.05 0.26"/>
    <limit effort="200" velocity="7.4799" lower="-0.5235988" upper="0.24497866" />
    <joint_properties damping="0.0" friction="0.05"/>
  </joint>

  <link name="back_left_upper">
    <visual>
    <origin rpy="0 0 0" xyz="0 0 -0.05"/>
      <geometry>
        <box size="0.03 0.02 0.1"/>
      </geometry>
    </visual>
    <collision>
    <origin rpy="0 0 0" xyz="0 0 -0.05"/>
      <geometry>
        <box size="0.03 0.02 0.1"/>
      </geometry>
    </collision>
    <inertial>
      <mass value="0.2"/>
      <inertia ixx="2.48333333e-4" ixy="0.0" ixz="0.0" iyy="8.83333333e-5" iyz="0.0" izz="1.73333333e-4"/>
    </inertial>
  </link>
  <joint name="back_left_shoulder" type="revolute">
    <axis xyz="0 1 0"/>
    <parent link="back_left_shoulder_blade"/>
    <child link="back_left_upper"/>
    <origin rpy="0 0 0" xyz="-0.025 -0.01 -0.03"/>
    <limit effort="530" velocity="8.7266" lower="-0.5235988" upper="1.48353" />
    <joint_properties damping="0.0" friction="0.05"/>
  </joint>

<link name="back_left_lower">
    <visual>
    <origin rpy="0 0 0" xyz="0 0 -0.05"/>
      <geometry>
        <cylinder length="0.095" radius="0.005"/>
      </geometry>
    </visual>
    <collision>
    <origin rpy="0 0 0" xyz="0 0 -0.05"/>
      <geometry>
        <cylinder length="0.095" radius="0.005"/>
      </geometry>
    </collision>
    <inertial>
      <mass value="0.15"/>
      <inertia ixx="1.25e-4" ixy="0.0" ixz="0.0" iyy="0.0" iyz="0.0" izz="1.25e-4"/>
    </inertial>
  </link>
  <joint name="back_left_knee" type="revolute">
    <axis xyz="0 1 0"/>
    <parent link="back_left_upper"/>
    <child link="back_left_lower"/>
    <origin rpy="0 0 0" xyz="0 0 -0.1"/>
    <limit effort="330" velocity="7.4799" lower="-0.5235988" upper="-2.094395" />
    <joint_properties damping="0.0" friction="0.05"/>
  </joint>

<link name="back_left_foot">
    <visual>
    <origin rpy="0 0 0" xyz="0 0 0"/>
      <geometry>
        <sphere radius="0.006"/>
      </geometry>
    </visual>
     <collision>
    <origin rpy="0 0 0" xyz="0 0 0"/>
      <geometry>
        <sphere radius="0.006"/>
      </geometry>
    </collision>
    <inertial>
      <mass value="0"/>
      <inertia ixx="0" ixy="0.0" ixz="0.0" iyy="0.0" iyz="0.0" izz="0"/>
    </inertial>
  </link>
  <joint name="back_left_sensor" type="fixed">
    <parent link="back_left_lower"/>
    <child link="back_left_foot"/>
    <origin rpy="0 0 0" xyz="0 0 -0.0975"/>
    <joint_properties damping="0.0" friction="0.05"/>
  </joint>

<link name="front_left_shoulder_blade">
    <visual>
    <origin rpy="0 0 0" xyz="0.035 -0.01 -0.015"/>
      <geometry>
        <box size="0.07 0.02 0.03"/>
      </geometry>
    </visual>
    <collision>
    <origin rpy="0 0 0" xyz="0.035 -0.01 -0.015"/>
      <geometry>
        <box size="0.07 0.02 0.03"/>
      </geometry>
    </collision>
    <inertial>
      <mass value="0.07"/>
      <inertia ixx="3.38333333e-5" ixy="0.0" ixz="0.0" iyy="3.09166667e-5" iyz="0.0" izz="7.58333333e-6"/>
    </inertial>
  </link>
  <joint name="front_left_base_to_shoulder" type="revolute">
    <axis xyz="1 0 0"/>
    <parent link="base_link"/>
    <child link="front_left_shoulder_blade"/>
    <origin rpy="0 0 0" xyz="-0.15 -0.05 0.26"/>
    <limit effort="200" velocity="7.4799" lower="-0.5235988" upper="0.24497866" />
    <joint_properties damping="0.0" friction="0.05"/>
  </joint>

  <link name="front_left_upper">
    <visual>
    <origin rpy="0 0 0" xyz="0 0 -0.05"/>
      <geometry>
        <box size="0.03 0.02 0.1"/>
      </geometry>
    </visual>
    <collision>
    <origin rpy="0 0 0" xyz="0 0 -0.05"/>
      <geometry>
        <box size="0.03 0.02 0.1"/>
      </geometry>
    </collision>
    <inertial>
      <mass value="0.2"/>
      <inertia ixx="2.48333333e-4" ixy="0.0" ixz="0.0" iyy="8.83333333e-5" iyz="0.0" izz="1.73333333e-4"/>
    </inertial>
  </link>
  <joint name="front_left_shoulder" type="revolute">
    <axis xyz="0 1 0"/>
    <parent link="front_left_shoulder_blade"/>
    <child link="front_left_upper"/>
    <origin rpy="0 0 0" xyz="0.025 -0.01 -0.03"/>
    <limit effort="530" velocity="8.7266" lower="-1.48353" upper="0.5235988" />
    <joint_properties damping="0.0" friction="0.05"/>
  </joint>

<link name="front_left_lower">
    <visual>
    <origin rpy="0 0 0" xyz="0 0 -0.05"/>
      <geometry>
        <cylinder length="0.095" radius="0.005"/>
      </geometry>
    </visual>
    <collision>
    <origin rpy="0 0 0" xyz="0 0 -0.05"/>
      <geometry>
        <cylinder length="0.095" radius="0.005"/>
      </geometry>
    </collision>
    <inertial>
      <mass value="0.15"/>
      <inertia ixx="1.25e-4" ixy="0.0" ixz="0.0" iyy="0.0" iyz="0.0" izz="1.25e-4"/>
    </inertial>
  </link>
  <joint name="front_left_knee" type="revolute">
    <axis xyz="0 1 0"/>
    <parent link="front_left_upper"/>
    <child link="front_left_lower"/>
    <origin rpy="0 0 0" xyz="0 0 -0.1"/>
    <limit effort="330" velocity="7.4799" lower="0.5235988" upper="2.094395" />
    <joint_properties damping="0.0" friction="0.05"/>
  </joint>

<link name="front_left_foot">
    <visual>
    <origin rpy="0 0 0" xyz="0 0 0"/>
      <geometry>
        <sphere radius="0.006"/>
      </geometry>
    </visual>
     <collision>
    <origin rpy="0 0 0" xyz="0 0 0"/>
      <geometry>
        <sphere radius="0.006"/>
      </geometry>
    </collision>
    <inertial>
      <mass value="0"/>
      <inertia ixx="0" ixy="0.0" ixz="0.0" iyy="0.0" iyz="0.0" izz="0"/>
    </inertial>
  </link>
   <joint name="front_left_sensor" type="fixed">
    <parent link="front_left_lower"/>
    <child link="front_left_foot"/>
    <origin rpy="0 0 0" xyz="0 0 -0.0975"/>
    <joint_properties damping="0.0" friction="0.05"/>
  </joint>


</robot>