<?xml version="1.0" ?>

<robot name="quad">
    <link name="base_link">
    <visual>
    <origin rpy="0 0 0" xyz="0 0 0"/>
      <geometry>
        <box size="0.32 0.1 0.1"/>
      </geometry>
    </visual>
    <collision>
    <origin rpy="0 0 0" xyz="0 0 0"/>
      <geometry>
       <box size="0.32 0.1 0.1"/>
      </geometry>
    </collision>
    <inertial>
      <mass value="2.5"/>
      <inertia ixx="0.00416667" ixy="0.0" ixz="0.0" iyy="0.023416667" iyz="0.0" izz="0.023416667"/>
        <origin  xyz="0 0 0"/>
    </inertial>
  </link>

<link name="base_sensor_weight">
    <visual>
    <origin rpy="0 0 0" xyz="0 0 0"/>
      <geometry>
        <sphere radius="0.01"/>
      </geometry>
    </visual>
     <collision>
    <origin rpy="0 0 0" xyz="0 0 0"/>
      <geometry>
        <sphere radius="0.01"/>
      </geometry>
    </collision>
    <inertial>
      <mass value="0.1"/>
      <inertia ixx="4e-6" ixy="0.0" ixz="0.0" iyy="4e-6" iyz="0.0" izz="4e-6"/>
    </inertial>
  </link>
  <joint name="base_sensor" type="fixed">
    <parent link="base_link"/>
    <child link="base_sensor_weight"/>
    <origin rpy="0 0 0" xyz="0 0 0"/>
    <joint_properties damping="0.0" friction="0.05"/>
  </joint>

<link name="back_right_shoulder_blade">
    <visual>
    <origin rpy="0 0 0" xyz="0.0 0.01 -0.015"/>
      <geometry>
        <box size="0.07 0.02 0.03"/>
      </geometry>
    </visual>
    <collision>
    <origin rpy="0 0 0" xyz="-0.035 -0.01 -0.015"/>
      <geometry>
        <box size="0.07 0.02 0.03"/>
      </geometry>
    </collision>
    <inertial>
      <mass value="0.25"/>
      <inertia ixx="3.38333333e-5" ixy="0.0" ixz="0.0" iyy="3.09166667e-5" iyz="0.0" izz="7.58333333e-6"/>
    </inertial>
  </link>
  <joint name="back_right_base_to_shoulder" type="revolute">
    <axis xyz="1 0 0"/>
    <parent link="base_link"/>
    <child link="back_right_shoulder_blade"/>
    <origin rpy="0 0 0" xyz="0.125 0.05 0.03"/>
    <limit effort="400" velocity="7.4799" lower="-0.24497866" upper="0.5235988" />
    <joint_properties damping="0.0" friction="0.05"/>
  </joint>

  <link name="back_right_upper">
    <visual>
    <origin rpy="0 0 0" xyz="0 0 -0.05"/>
      <geometry>
        <box size="0.03 0.02 0.1"/>
      </geometry>
    </visual>
    <collision>
    <origin rpy="0 0 0" xyz="0 0 -0.05"/>
      <geometry>
        <box size="0.03 0.02 0.1"/>
      </geometry>
    </collision>
    <inertial>
      <mass value="0.2"/>
      <inertia ixx="0.0001733333" ixy="0.0" ixz="0.0" iyy="0.000181666666667" iyz="0.0" izz="2.1666666667e-05"/>
    </inertial>
  </link>
  <joint name="back_right_shoulder" type="revolute">
    <axis xyz="0 1 0"/>
    <parent link="back_right_shoulder_blade"/>
    <child link="back_right_upper"/>
    <origin rpy="0 0 0" xyz="0.0 0.01 -0.015"/>
    <limit effort="530" velocity="8.7266" lower="-1.309" upper="1.309" />
    <joint_properties damping="0.0" friction="0.05"/>
  </joint>

<link name="back_right_mid">
    <visual>
    <origin rpy="0 0 0" xyz="0 0 -0.05"/>
      <geometry>
        <cylinder length="0.1" radius="0.005"/>
      </geometry>
    </visual>
    <collision>
    <origin rpy="0 0 0" xyz="0 0 -0.05"/>
      <geometry>
        <cylinder length="0.1" radius="0.005"/>
      </geometry>
    </collision>
    <inertial>
      <mass value="0.01"/>
      <inertia ixx="0.0003333333333333334" ixy="0.0" ixz="0.0" iyy="0.0" iyz="0.0" izz="0.0003333333333333334"/>
    </inertial>
  </link>
  <joint name="back_right_knee" type="revolute">
    <axis xyz="0 1 0"/>
    <parent link="back_right_upper"/>
    <child link="back_right_mid"/>
    <origin rpy="0 0 0" xyz="0 0 -0.1"/>
    <limit effort="530" velocity="8.7266" lower="-0.5235988" upper="-2.6179938" />
    <joint_properties damping="0.0" friction="0.05"/>
  </joint>

<link name="back_right_lower">
    <visual>
    <origin rpy="0 0 0" xyz="0 0 -0.046"/>
      <geometry>
        <cylinder length="0.092" radius="0.005"/>
      </geometry>
    </visual>
    <collision>
    <origin rpy="0 0 0" xyz="0 0 -0.046"/>
      <geometry>
        <cylinder length="0.092" radius="0.005"/>
      </geometry>
    </collision>
    <inertial>
      <mass value="0.1"/>
      <inertia ixx="0.003066666666666667" ixy="0.0" ixz="0.0" iyy="0.0" iyz="0.0" izz="0.003066666666666667"/>
    </inertial>
  </link>
  <joint name="back_right_heel" type="revolute">
    <axis xyz="0 1 0"/>
    <parent link="back_right_mid"/>
    <child link="back_right_lower"/>
    <origin rpy="0 0 0" xyz="0 0 -0.1"/>
    <limit effort="530" velocity="8.7266" lower="0.5235988" upper="2.6179938" />
    <joint_properties damping="0.0" friction="0.05"/>
  </joint>

<link name="back_right_dampener">
    <visual>
    <origin rpy="0 0 0" xyz="0 0 -0.05"/>
      <geometry>
        <cylinder length="0.02" radius="0.006"/>
      </geometry>
    </visual>
    <collision>
    <origin rpy="0 0 0" xyz="0 0 -0.05"/>
      <geometry>
        <cylinder length="0.02" radius="0.006"/>
      </geometry>
    </collision>
    <inertial>
      <mass value="0.025"/>
      <inertia ixx="4.166666666666667e-06" ixy="0.0" ixz="0.0" iyy="0.0" iyz="0.0" izz="4.166666666666667e-06"/>
    </inertial>
  </link>
  <joint name="back_right_damp_joint" type="prismatic">
    <axis xyz="0 0 1"/>
    <parent link="back_right_lower"/>
    <child link="back_right_dampener"/>
    <origin rpy="0 0 0" xyz="0 0 -0.046"/>
    <limit  lower="0.0" upper="0.012" />
    <joint_properties damping="0.05" friction="0.05"/>
  </joint>

<link name="back_right_foot">
    <visual>
    <origin rpy="0 0 0" xyz="0 0 0"/>
      <geometry>
        <sphere radius="0.008"/>
      </geometry>
    </visual>
     <collision>
    <origin rpy="0 0 0" xyz="0 0 0"/>
      <geometry>
        <sphere radius="0.008"/>
      </geometry>
    </collision>
    <inertial>
      <mass value="0.025"/>
      <inertia ixx="6.400000000000001e-07" ixy="0.0" ixz="0.0" iyy="6.400000000000001e-07" iyz="0.0" izz="6.400000000000001e-07"/>
    </inertial>
  </link>
   <joint name="back_right_sensor" type="fixed">
    <parent link="back_right_dampener"/>
    <child link="back_right_foot"/>
    <origin rpy="0 -0.7853981633974483 0" xyz="0 0 -0.063"/>
    <joint_properties damping="0.0" friction="0.05"/>
  </joint>

<link name="front_right_shoulder_blade">
    <visual>
    <origin rpy="0 0 0" xyz="0.0 0.01 -0.015"/>
      <geometry>
        <box size="0.07 0.02 0.03"/>
      </geometry>
    </visual>
    <collision>
    <origin rpy="0 0 0" xyz="-0.035 -0.01 -0.015"/>
      <geometry>
        <box size="0.07 0.02 0.03"/>
      </geometry>
    </collision>
    <inertial>
      <mass value="0.25"/>
      <inertia ixx="3.38333333e-5" ixy="0.0" ixz="0.0" iyy="3.09166667e-5" iyz="0.0" izz="7.58333333e-6"/>
    </inertial>
  </link>
  <joint name="front_right_base_to_shoulder" type="revolute">
    <axis xyz="1 0 0"/>
    <parent link="base_link"/>
    <child link="front_right_shoulder_blade"/>
    <origin rpy="0 0 0" xyz="-0.125 0.05 0.03"/>
    <limit effort="400" velocity="7.4799" lower="-0.24497866" upper="0.5235988" />
    <joint_properties damping="0.0" friction="0.05"/>
  </joint>

  <link name="front_right_upper">
    <visual>
    <origin rpy="0 0 0" xyz="0 0 -0.05"/>
      <geometry>
        <box size="0.03 0.02 0.1"/>
      </geometry>
    </visual>
    <collision>
    <origin rpy="0 0 0" xyz="0 0 -0.05"/>
      <geometry>
        <box size="0.03 0.02 0.1"/>
      </geometry>
    </collision>
    <inertial>
      <mass value="0.2"/>
      <inertia ixx="0.0001733333" ixy="0.0" ixz="0.0" iyy="0.000181666666667" iyz="0.0" izz="2.1666666667e-05"/>
    </inertial>
  </link>
  <joint name="front_right_shoulder" type="revolute">
    <axis xyz="0 1 0"/>
    <parent link="front_right_shoulder_blade"/>
    <child link="front_right_upper"/>
    <origin rpy="0 0 0" xyz="0.0 0.01 -0.015"/>
    <limit effort="530" velocity="8.7266" lower="-1.309" upper="1.309" />
    <joint_properties damping="0.0" friction="0.05"/>
  </joint>

<link name="front_right_mid">
    <visual>
    <origin rpy="0 0 0" xyz="0 0 -0.05"/>
      <geometry>
        <cylinder length="0.1" radius="0.005"/>
      </geometry>
    </visual>
    <collision>
    <origin rpy="0 0 0" xyz="0 0 -0.05"/>
      <geometry>
        <cylinder length="0.1" radius="0.005"/>
      </geometry>
    </collision>
    <inertial>
      <mass value="0.01"/>
      <inertia ixx="0.0003333333333333334" ixy="0.0" ixz="0.0" iyy="0.0" iyz="0.0" izz="0.0003333333333333334"/>
    </inertial>
  </link>
  <joint name="front_right_knee" type="revolute">
    <axis xyz="0 1 0"/>
    <parent link="front_right_upper"/>
    <child link="front_right_mid"/>
    <origin rpy="0 0 0" xyz="0 0 -0.1"/>
    <limit effort="530" velocity="8.7266" lower="-0.5235988" upper="-2.6179938" />
    <joint_properties damping="0.0" friction="0.05"/>
  </joint>

<link name="front_right_lower">
    <visual>
    <origin rpy="0 0 0" xyz="0 0 -0.046"/>
      <geometry>
        <cylinder length="0.092" radius="0.005"/>
      </geometry>
    </visual>
    <collision>
    <origin rpy="0 0 0" xyz="0 0 -0.046"/>
      <geometry>
        <cylinder length="0.092" radius="0.005"/>
      </geometry>
    </collision>
    <inertial>
      <mass value="0.1"/>
      <inertia ixx="0.003066666666666667" ixy="0.0" ixz="0.0" iyy="0.0" iyz="0.0" izz="0.003066666666666667"/>
    </inertial>
  </link>
  <joint name="front_right_heel" type="revolute">
    <axis xyz="0 1 0"/>
    <parent link="front_right_mid"/>
    <child link="front_right_lower"/>
    <origin rpy="0 0 0" xyz="0 0 -0.1"/>
    <limit effort="530" velocity="8.7266" lower="0.5235988" upper="2.6179938" />
    <joint_properties damping="0.0" friction="0.05"/>
  </joint>

<link name="front_right_dampener">
    <visual>
    <origin rpy="0 0 0" xyz="0 0 -0.05"/>
      <geometry>
        <cylinder length="0.02" radius="0.006"/>
      </geometry>
    </visual>
    <collision>
    <origin rpy="0 0 0" xyz="0 0 -0.05"/>
      <geometry>
        <cylinder length="0.02" radius="0.006"/>
      </geometry>
    </collision>
    <inertial>
      <mass value="0.025"/>
      <inertia ixx="4.166666666666667e-06" ixy="0.0" ixz="0.0" iyy="0.0" iyz="0.0" izz="4.166666666666667e-06"/>
    </inertial>
  </link>
  <joint name="front_right_damp_joint" type="prismatic">
    <axis xyz="0 0 1"/>
    <parent link="front_right_lower"/>
    <child link="front_right_dampener"/>
    <origin rpy="0 0 0" xyz="0 0 -0.046"/>
    <limit  lower="0.0" upper="0.012" />
    <joint_properties damping="0.05" friction="0.05"/>
  </joint>

<link name="front_right_foot">
    <visual>
    <origin rpy="0 0 0" xyz="0 0 0"/>
      <geometry>
        <sphere radius="0.008"/>
      </geometry>
    </visual>
     <collision>
    <origin rpy="0 0 0" xyz="0 0 0"/>
      <geometry>
        <sphere radius="0.008"/>
      </geometry>
    </collision>
    <inertial>
      <mass value="0.025"/>
      <inertia ixx="6.400000000000001e-07" ixy="0.0" ixz="0.0" iyy="6.400000000000001e-07" iyz="0.0" izz="6.400000000000001e-07"/>
    </inertial>
  </link>
   <joint name="front_right_sensor" type="fixed">
    <parent link="front_right_dampener"/>
    <child link="front_right_foot"/>
    <origin rpy="0 -0.7853981633974483 0" xyz="0 0 -0.063"/>
    <joint_properties damping="0.0" friction="0.05"/>
  </joint>

<link name="back_left_shoulder_blade">
    <visual>
    <origin rpy="0 0 0" xyz="0.0 -0.01 -0.015"/>
      <geometry>
        <box size="0.07 0.02 0.03"/>
      </geometry>
    </visual>
    <collision>
    <origin rpy="0 0 0" xyz="-0.035 -0.01 -0.015"/>
      <geometry>
        <box size="0.07 0.02 0.03"/>
      </geometry>
    </collision>
    <inertial>
      <mass value="0.25"/>
      <inertia ixx="3.38333333e-5" ixy="0.0" ixz="0.0" iyy="3.09166667e-5" iyz="0.0" izz="7.58333333e-6"/>
    </inertial>
  </link>
  <joint name="back_left_base_to_shoulder" type="revolute">
    <axis xyz="1 0 0"/>
    <parent link="base_link"/>
    <child link="back_left_shoulder_blade"/>
    <origin rpy="0 0 0" xyz="0.125 -0.05 0.03"/>
    <limit effort="400" velocity="7.4799" lower="-0.5235988" upper="0.24497866" />
    <joint_properties damping="0.0" friction="0.05"/>
  </joint>

  <link name="back_left_upper">
    <visual>
    <origin rpy="0 0 0" xyz="0 0 -0.05"/>
      <geometry>
        <box size="0.03 0.02 0.1"/>
      </geometry>
    </visual>
    <collision>
    <origin rpy="0 0 0" xyz="0 0 -0.05"/>
      <geometry>
        <box size="0.03 0.02 0.1"/>
      </geometry>
    </collision>
    <inertial>
      <mass value="0.2"/>
      <inertia ixx="0.0001733333" ixy="0.0" ixz="0.0" iyy="0.000181666666667" iyz="0.0" izz="2.1666666667e-05"/>
    </inertial>
  </link>
  <joint name="back_left_shoulder" type="revolute">
    <axis xyz="0 1 0"/>
    <parent link="back_left_shoulder_blade"/>
    <child link="back_left_upper"/>
    <origin rpy="0 0 0" xyz="0.0 -0.01 -0.015"/>
    <limit effort="530" velocity="8.7266" lower="-1.309" upper="1.309" />
    <joint_properties damping="0.0" friction="0.05"/>
  </joint>

<link name="back_left_mid">
    <visual>
    <origin rpy="0 0 0" xyz="0 0 -0.05"/>
      <geometry>
        <cylinder length="0.1" radius="0.005"/>
      </geometry>
    </visual>
    <collision>
    <origin rpy="0 0 0" xyz="0 0 -0.05"/>
      <geometry>
        <cylinder length="0.1" radius="0.005"/>
      </geometry>
    </collision>
    <inertial>
      <mass value="0.01"/>
      <inertia ixx="0.0003333333333333334" ixy="0.0" ixz="0.0" iyy="0.0" iyz="0.0" izz="0.0003333333333333334"/>
    </inertial>
  </link>
  <joint name="back_left_knee" type="revolute">
    <axis xyz="0 1 0"/>
    <parent link="back_left_upper"/>
    <child link="back_left_mid"/>
    <origin rpy="0 0 0" xyz="0 0 -0.1"/>
    <limit effort="530" velocity="8.7266" lower="-0.5235988" upper="-2.6179938" />
    <joint_properties damping="0.0" friction="0.05"/>
  </joint>

<link name="back_left_lower">
    <visual>
    <origin rpy="0 0 0" xyz="0 0 -0.046"/>
      <geometry>
        <cylinder length="0.092" radius="0.005"/>
      </geometry>
    </visual>
    <collision>
    <origin rpy="0 0 0" xyz="0 0 -0.046"/>
      <geometry>
        <cylinder length="0.092" radius="0.005"/>
      </geometry>
    </collision>
    <inertial>
      <mass value="0.1"/>
      <inertia ixx="0.003066666666666667" ixy="0.0" ixz="0.0" iyy="0.0" iyz="0.0" izz="0.003066666666666667"/>
    </inertial>
  </link>
  <joint name="back_left_heel" type="revolute">
    <axis xyz="0 1 0"/>
    <parent link="back_left_mid"/>
    <child link="back_left_lower"/>
    <origin rpy="0 0 0" xyz="0 0 -0.1"/>
    <limit effort="530" velocity="8.7266" lower="0.5235988" upper="2.6179938" />
    <joint_properties damping="0.0" friction="0.05"/>
  </joint>

<link name="back_left_dampener">
    <visual>
    <origin rpy="0 0 0" xyz="0 0 -0.05"/>
      <geometry>
        <cylinder length="0.02" radius="0.006"/>
      </geometry>
    </visual>
    <collision>
    <origin rpy="0 0 0" xyz="0 0 -0.05"/>
      <geometry>
        <cylinder length="0.02" radius="0.006"/>
      </geometry>
    </collision>
    <inertial>
      <mass value="0.025"/>
      <inertia ixx="4.166666666666667e-06" ixy="0.0" ixz="0.0" iyy="0.0" iyz="0.0" izz="4.166666666666667e-06"/>
    </inertial>
  </link>
  <joint name="back_left_damp_joint" type="prismatic">
    <axis xyz="0 0 1"/>
    <parent link="back_left_lower"/>
    <child link="back_left_dampener"/>
    <origin rpy="0 0 0" xyz="0 0 -0.046"/>
    <limit  lower="0.0" upper="0.012" />
    <joint_properties damping="0.05" friction="0.05"/>
  </joint>

<link name="back_left_foot">
    <visual>
    <origin rpy="0 0 0" xyz="0 0 0"/>
      <geometry>
        <sphere radius="0.008"/>
      </geometry>
    </visual>
     <collision>
    <origin rpy="0 0 0" xyz="0 0 0"/>
      <geometry>
        <sphere radius="0.008"/>
      </geometry>
    </collision>
    <inertial>
      <mass value="0.025"/>
      <inertia ixx="6.400000000000001e-07" ixy="0.0" ixz="0.0" iyy="6.400000000000001e-07" iyz="0.0" izz="6.400000000000001e-07"/>
    </inertial>
  </link>
   <joint name="back_left_sensor" type="fixed">
    <parent link="back_left_dampener"/>
    <child link="back_left_foot"/>
    <origin rpy="0 -0.7853981633974483 0" xyz="0 0 -0.063"/>
    <joint_properties damping="0.0" friction="0.05"/>
  </joint>

<link name="front_left_shoulder_blade">
    <visual>
    <origin rpy="0 0 0" xyz="0.0 -0.01 -0.015"/>
      <geometry>
        <box size="0.07 0.02 0.03"/>
      </geometry>
    </visual>
    <collision>
    <origin rpy="0 0 0" xyz="-0.035 -0.01 -0.015"/>
      <geometry>
        <box size="0.07 0.02 0.03"/>
      </geometry>
    </collision>
    <inertial>
      <mass value="0.25"/>
      <inertia ixx="3.38333333e-5" ixy="0.0" ixz="0.0" iyy="3.09166667e-5" iyz="0.0" izz="7.58333333e-6"/>
    </inertial>
  </link>
  <joint name="front_left_base_to_shoulder" type="revolute">
    <axis xyz="1 0 0"/>
    <parent link="base_link"/>
    <child link="front_left_shoulder_blade"/>
    <origin rpy="0 0 0" xyz="-0.125 -0.05 0.03"/>
    <limit effort="400" velocity="7.4799" lower="-0.5235988" upper="0.24497866" />
    <joint_properties damping="0.0" friction="0.05"/>
  </joint>

  <link name="front_left_upper">
    <visual>
    <origin rpy="0 0 0" xyz="0 0 -0.05"/>
      <geometry>
        <box size="0.03 0.02 0.1"/>
      </geometry>
    </visual>
    <collision>
    <origin rpy="0 0 0" xyz="0 0 -0.05"/>
      <geometry>
        <box size="0.03 0.02 0.1"/>
      </geometry>
    </collision>
    <inertial>
      <mass value="0.2"/>
      <inertia ixx="0.0001733333" ixy="0.0" ixz="0.0" iyy="0.000181666666667" iyz="0.0" izz="2.1666666667e-05"/>
    </inertial>
  </link>
  <joint name="front_left_shoulder" type="revolute">
    <axis xyz="0 1 0"/>
    <parent link="front_left_shoulder_blade"/>
    <child link="front_left_upper"/>
    <origin rpy="0 0 0" xyz="0.0 -0.01 -0.015"/>
    <limit effort="530" velocity="8.7266" lower="-1.309" upper="1.309" />
    <joint_properties damping="0.0" friction="0.05"/>
  </joint>

<link name="front_left_mid">
    <visual>
    <origin rpy="0 0 0" xyz="0 0 -0.05"/>
      <geometry>
        <cylinder length="0.1" radius="0.005"/>
      </geometry>
    </visual>
    <collision>
    <origin rpy="0 0 0" xyz="0 0 -0.05"/>
      <geometry>
        <cylinder length="0.1" radius="0.005"/>
      </geometry>
    </collision>
    <inertial>
      <mass value="0.01"/>
      <inertia ixx="0.0003333333333333334" ixy="0.0" ixz="0.0" iyy="0.0" iyz="0.0" izz="0.0003333333333333334"/>
    </inertial>
  </link>
  <joint name="front_left_knee" type="revolute">
    <axis xyz="0 1 0"/>
    <parent link="front_left_upper"/>
    <child link="front_left_mid"/>
    <origin rpy="0 0 0" xyz="0 0 -0.1"/>
    <limit effort="530" velocity="8.7266" lower="-0.5235988" upper="-2.6179938" />
    <joint_properties damping="0.0" friction="0.05"/>
  </joint>

<link name="front_left_lower">
    <visual>
    <origin rpy="0 0 0" xyz="0 0 -0.046"/>
      <geometry>
        <cylinder length="0.092" radius="0.005"/>
      </geometry>
    </visual>
    <collision>
    <origin rpy="0 0 0" xyz="0 0 -0.046"/>
      <geometry>
        <cylinder length="0.092" radius="0.005"/>
      </geometry>
    </collision>
    <inertial>
      <mass value="0.1"/>
      <inertia ixx="0.003066666666666667" ixy="0.0" ixz="0.0" iyy="0.0" iyz="0.0" izz="0.003066666666666667"/>
    </inertial>
  </link>
  <joint name="front_left_heel" type="revolute">
    <axis xyz="0 1 0"/>
    <parent link="front_left_mid"/>
    <child link="front_left_lower"/>
    <origin rpy="0 0 0" xyz="0 0 -0.1"/>
    <limit effort="530" velocity="8.7266" lower="0.5235988" upper="2.6179938" />
    <joint_properties damping="0.0" friction="0.05"/>
  </joint>

<link name="front_left_dampener">
    <visual>
    <origin rpy="0 0 0" xyz="0 0 -0.05"/>
      <geometry>
        <cylinder length="0.02" radius="0.006"/>
      </geometry>
    </visual>
    <collision>
    <origin rpy="0 0 0" xyz="0 0 -0.05"/>
      <geometry>
        <cylinder length="0.02" radius="0.006"/>
      </geometry>
    </collision>
    <inertial>
      <mass value="0.025"/>
      <inertia ixx="4.166666666666667e-06" ixy="0.0" ixz="0.0" iyy="0.0" iyz="0.0" izz="4.166666666666667e-06"/>
    </inertial>
  </link>
  <joint name="front_left_damp_joint" type="prismatic">
    <axis xyz="0 0 1"/>
    <parent link="front_left_lower"/>
    <child link="front_left_dampener"/>
    <origin rpy="0 0 0" xyz="0 0 -0.046"/>
    <limit  lower="0.0" upper="0.012" />
    <joint_properties damping="0.05" friction="0.05"/>
  </joint>

<link name="front_left_foot">
    <visual>
    <origin rpy="0 0 0" xyz="0 0 0"/>
      <geometry>
        <sphere radius="0.008"/>
      </geometry>
    </visual>
     <collision>
    <origin rpy="0 0 0" xyz="0 0 0"/>
      <geometry>
        <sphere radius="0.008"/>
      </geometry>
    </collision>
    <inertial>
      <mass value="0.025"/>
      <inertia ixx="6.400000000000001e-07" ixy="0.0" ixz="0.0" iyy="6.400000000000001e-07" iyz="0.0" izz="6.400000000000001e-07"/>
    </inertial>
  </link>
   <joint name="front_left_sensor" type="fixed">
    <parent link="front_left_dampener"/>
    <child link="front_left_foot"/>
    <origin rpy="0 -0.7853981633974483 0" xyz="0 0 -0.063"/>
    <joint_properties damping="0.0" friction="0.05"/>
  </joint>

</robot>